<mujoco model="MuJoCo Model">
  <compiler angle="radian"/>

  <worldbody>
    <body name="torso" pos="0 0 0.5">
      <joint name="torso_joint" type="free" limited="false" actuatorfrclimited="false"/>
      <geom size="0.275 0.125 0.1" type="box" mass="36"/>
      <body name="torso_left_thigh" pos="-0.13 0.125 0">
        <joint name="torso_left_thigh_joint" pos="0 0 0" axis="0 1 0" armature="0.08" damping="2"/>
        <geom name="torso_left_thigh_geom" size="0.04 0.125" pos="0 0.04 -0.125" type="capsule" mass="3"/>
        <body name="torso_left_shin" pos="0 0.12 -0.25">
          <joint name="torso_left_thigh_shin_joint" pos="0 0 0" axis="0 1 0" armature="0.08" damping="2"/>
          <geom name="torso_left_shin_geom" size="0.04 0.15" quat="0.707107 0 0.707107 0" type="capsule" mass="2"/>
          <body name="torso_left_front_wheel" pos="0.15 0.09 0">
            <joint name="torso_left_shin_front_wheel_joint" pos="0 0 0" axis="0 1 0" armature="0.004" damping="2"/>
            <geom name="torso_left_front_wheel_geom" size="0.12 0.12 0.05" quat="0.707107 0.707107 0 0" type="ellipsoid" friction="0.9 0.5 0.05" solref="0.1 0.1" mass="2"/>
          </body>
          <body name="torso_left_rear_wheel" pos="-0.15 0.09 0">
            <joint name="torso_left_shin_rear_wheel_joint" pos="0 0 0" axis="0 1 0" armature="0.004" damping="2"/>
            <geom name="torso_left_rear_wheel_geom" size="0.12 0.12 0.05" quat="0.707107 0.707107 0 0" type="ellipsoid" friction="0.9 0.5 0.05" solref="0.1 0.1" mass="2"/>
          </body>
        </body>
      </body>
      <body name="torso_right_thigh" pos="-0.13 -0.125 0">
        <joint name="torso_right_thigh_joint" pos="0 0 0" axis="0 1 0" armature="0.08" damping="2"/>
        <geom name="torso_right_thigh_geom" size="0.04 0.125" pos="0 -0.04 -0.125" type="capsule" mass="3"/>
        <body name="torso_right_shin" pos="0 -0.12 -0.25">
          <joint name="torso_right_thigh_shin_joint" pos="0 0 0" axis="0 1 0" armature="0.08" damping="2"/>
          <geom name="torso_right_shin_geom" size="0.04 0.15" quat="0.707107 0 0.707107 0" type="capsule" mass="2"/>
          <body name="torso_right_front_wheel" pos="0.15 -0.09 0">
            <joint name="torso_right_shin_front_wheel_joint" pos="0 0 0" axis="0 1 0" armature="0.004" damping="2"/>
            <geom name="torso_right_front_wheel_geom" size="0.12 0.12 0.05" quat="0.707107 0.707107 0 0" type="ellipsoid" friction="0.9 0.5 0.05" solref="0.1 0.1" mass="2"/>
          </body>
          <body name="torso_right_rear_wheel" pos="-0.15 -0.09 0">
            <joint name="torso_right_shin_rear_wheel_joint" pos="0 0 0" axis="0 1 0" armature="0.004" damping="2"/>
            <geom name="torso_right_rear_wheel_geom" size="0.12 0.12 0.05" quat="0.707107 0.707107 0 0" type="ellipsoid" friction="0.9 0.5 0.05" solref="0.1 0.1" mass="2"/>
          </body>
        </body>
      </body>
      <body name="head" pos="0.425 0 0">
        <joint name="head_joint" pos="-0.1 0 0" axis="1 0 0" range="-0.436332 0.436332"/>
        <geom size="0.1 0.125 0.1" type="box" mass="15"/>
        <body name="head_left_thigh" pos="0 0.125 0">
          <joint name="head_left_thigh_joint" pos="0 0 0" axis="0 1 0" armature="0.08" damping="2"/>
          <geom name="head_left_thigh_geom" size="0.04 0.125" pos="0 0.04 -0.125" type="capsule" mass="3"/>
          <body name="head_left_shin" pos="0 0.12 -0.25">
            <joint name="head_left_thigh_shin_joint" pos="0 0 0" axis="0 1 0" armature="0.08" damping="2"/>
            <geom name="head_left_shin_geom" size="0.04 0.15" quat="0.707107 0 0.707107 0" type="capsule" mass="2"/>
            <body name="head_left_front_wheel" pos="0.15 0.09 0">
              <joint name="head_left_shin_front_wheel_joint" pos="0 0 0" axis="0 1 0" armature="0.004" damping="2"/>
              <geom name="head_left_front_wheel_geom" size="0.12 0.12 0.05" quat="0.707107 0.707107 0 0" type="ellipsoid" friction="0.9 0.5 0.05" solref="0.1 0.1" mass="2"/>
            </body>
            <body name="head_left_rear_wheel" pos="-0.15 0.09 0">
              <joint name="head_left_shin_rear_wheel_joint" pos="0 0 0" axis="0 1 0" armature="0.004" damping="2"/>
              <geom name="head_left_rear_wheel_geom" size="0.12 0.12 0.05" quat="0.707107 0.707107 0 0" type="ellipsoid" friction="0.9 0.5 0.05" solref="0.1 0.1" mass="2"/>
            </body>
          </body>
        </body>
        <body name="head_right_thigh" pos="0 -0.125 0">
          <joint name="head_right_thigh_joint" pos="0 0 0" axis="0 1 0" armature="0.08" damping="2"/>
          <geom name="head_right_thigh_geom" size="0.04 0.125" pos="0 -0.04 -0.125" type="capsule" mass="3"/>
          <body name="head_right_shin" pos="0 -0.12 -0.25">
            <joint name="head_right_thigh_shin_joint" pos="0 0 0" axis="0 1 0" armature="0.08" damping="2"/>
            <geom name="head_right_shin_geom" size="0.04 0.15" quat="0.707107 0 0.707107 0" type="capsule" mass="2"/>
            <body name="head_right_front_wheel" pos="0.15 -0.09 0">
              <joint name="head_right_shin_front_wheel_joint" pos="0 0 0" axis="0 1 0" armature="0.004" damping="2"/>
              <geom name="head_right_front_wheel_geom" size="0.12 0.12 0.05" quat="0.707107 0.707107 0 0" type="ellipsoid" friction="0.9 0.5 0.05" solref="0.1 0.1" mass="2"/>
            </body>
            <body name="head_right_rear_wheel" pos="-0.15 -0.09 0">
              <joint name="head_right_shin_rear_wheel_joint" pos="0 0 0" axis="0 1 0" armature="0.004" damping="2"/>
              <geom name="head_right_rear_wheel_geom" size="0.12 0.12 0.05" quat="0.707107 0.707107 0 0" type="ellipsoid" friction="0.9 0.5 0.05" solref="0.1 0.1" mass="2"/>
            </body>
          </body>
        </body>
      </body>
    </body>
  </worldbody>

  <actuator>
    <general name="bl_hip" joint="torso_left_thigh_joint"/>
    <general name="bl_knee" joint="torso_left_thigh_shin_joint"/>
    <general name="bl_wheel1_joint" joint="torso_left_shin_front_wheel_joint"/>
    <general name="bl_wheel2_joint" joint="torso_left_shin_rear_wheel_joint"/>
    <general name="br_hip" joint="torso_right_thigh_joint"/>
    <general name="br_knee" joint="torso_right_thigh_shin_joint"/>
    <general name="br_wheel1_joint" joint="torso_right_shin_front_wheel_joint"/>
    <general name="br_wheel2_joint" joint="torso_right_shin_rear_wheel_joint"/>
    <general name="fl_hip" joint="head_left_thigh_joint"/>
    <general name="fl_knee" joint="head_left_thigh_shin_joint"/>
    <general name="fl_wheel1_joint" joint="head_left_shin_front_wheel_joint"/>
    <general name="fl_wheel2_joint" joint="head_left_shin_rear_wheel_joint"/>
    <general name="fr_hip" joint="head_right_thigh_joint"/>
    <general name="fr_knee" joint="head_right_thigh_shin_joint"/>
    <general name="fr_wheel1_joint" joint="head_right_shin_front_wheel_joint"/>
    <general name="fr_wheel2_joint" joint="head_right_shin_rear_wheel_joint"/>
  </actuator>
</mujoco>
